<?xml version="1.0"?>
<robot name="macroed" xmlns:xacro="http://ros.org/wiki/xacro">

    <!-- Parametros DH -->
    <xacro:property name="Elo1_theta" value="livre" />
    <xacro:property name="Elo1_alfa" value="${pi}" />
    <xacro:property name="Elo1_a" value="0" />
    <xacro:property name="Elo1_d" value="0.5" />
    
    <xacro:property name="Elo2_theta" value="0" />
    <xacro:property name="Elo2_alfa" value="0" />
    <xacro:property name="Elo2_a" value="0.25" />
    <xacro:property name="Elo2_d" value="livre" />
    
    <xacro:property name="Elo3_theta" value="livre" />
    <xacro:property name="Elo3_alfa" value="0" />
    <xacro:property name="Elo3_a" value="0" />
    <xacro:property name="Elo3_d" value="0.1" />
    
    <xacro:property name="Elo4_theta" value="livre" />
    <xacro:property name="Elo4_alfa" value="0" />
    <xacro:property name="Elo4_a" value="0.25" />
    <xacro:property name="Elo4_d" value="0.1" />

    <!-- Medidas de colisao -->
    <xacro:property name="RaioBase" value="0.1000" />
    <xacro:property name="AlturaBase" value="0.1000" />

    <xacro:property name="AlturaOmbro" value="0.3000" />
    <xacro:property name="larguraOmbro" value="0.1100" />
    <xacro:property name="ComprimentoOmbro" value="0.1500" />

    <xacro:property name="RaioBraco" value="0.1000" />
    <xacro:property name="AlturaBraco" value="0.0850" />

    <xacro:property name="RaioAntebraco" value="0.0800" />
    <xacro:property name="AlturaAntebraco" value="0.0800" />

    <xacro:property name="AlturaFerramenta" value="0.0500" />
    <xacro:property name="larguraFerramenta" value="0.0500" />
    <xacro:property name="ComprimentoFerramenta" value="0.0500" />

    <material name="blue">
    <color rgba="0 0 0.8 1"/>
    </material>

    <link name="base_link">
        <visual>
            <geometry>
                <mesh filename="package://bres/meshes/3d_base.stl"/>
            </geometry>
            <material name="blue"/>
            <origin xyz="0 0 ${AlturaBase/2}" />
        </visual>
        <collision>
            <geometry>
                <cylinder radius="${RaioBase}" length="${AlturaBase}"/>
            </geometry>
            <material name="blue"/>
            <origin xyz="0 0 ${AlturaBase/2}" />
        </collision>
    </link>

    <link name="Ombro">
        <visual>
            <geometry>
                <box size="${ComprimentoOmbro} ${larguraOmbro} ${AlturaOmbro}"/>
            </geometry>
            <material name="blue"/>
            <origin xyz="0 0 ${AlturaOmbro/2}" />
        </visual>
    </link>

    <!-- Junta 1 -->
    <joint name="base_to_Ombro" type="revolute">
        <parent link="base_link"/>
        <child link="Ombro"/>
        <axis xyz="0 0 1"/>
        <limit effort="1000.0" lower="0.0" upper="0.548" velocity="0.5"/>
        <origin xyz="${Elo1_a} 0 ${Elo1_d}" rpy="${Elo1_alfa} 0 0" />
    </joint>

    <link name="Braco">
        <visual>
            <geometry>
                <cylinder radius="${RaioBraco}" length="${AlturaBraco}"/>
            </geometry>
            <material name="blue"/>
            <origin xyz="0 0 ${AlturaBraco/2}" />
        </visual>
    </link>

   <!-- Junta 2 -->
    <joint name="Ombro_to_Braco" type="prismatic">
        <parent link="Ombro"/>
        <child link="Braco"/>
        <axis xyz="0 0 1"/>
        <limit effort="1000.0" lower="0" upper="0.1" velocity="0.5"/>
        <origin xyz="${Elo2_a} 0 0" rpy="${Elo2_alfa} 0 ${Elo2_theta}" />
    </joint>

    <link name="Antebraco">
        <visual>
            <geometry>
                <cylinder radius="${RaioAntebraco}" length="${AlturaAntebraco}"/>
            </geometry>
            <material name="blue"/>
            <origin xyz="0 0 ${AlturaAntebraco/2}" />
        </visual>
    </link>

    <!-- Junta 3 -->
    <joint name="Braco_to_Antebraco" type="revolute">
        <parent link="Braco"/>
        <child link="Antebraco"/>
        <axis xyz="0 0 1"/>
        <limit effort="1000.0" lower="0.0" upper="0.548" velocity="0.5"/>
        <origin xyz="${Elo3_a} 0 ${Elo3_d}" rpy="${Elo3_alfa} 0 0" />
    </joint>

    <link name="Ferramenta">
        <visual>
            <geometry>
                <box size="${ComprimentoFerramenta} ${larguraFerramenta} ${AlturaFerramenta}"/>
            </geometry>
            <material name="blue"/>
            <origin xyz="0 0 ${AlturaFerramenta/2}" />
        </visual>
    </link>

    <!-- Junta 4 -->
    <joint name="Antebraco_to_Ferramenta" type="revolute">
        <parent link="Antebraco"/>
        <child link="Ferramenta"/>
        <axis xyz="0 0 1"/>
        <limit effort="1000.0" lower="0.0" upper="0.548" velocity="0.5"/>
        <origin xyz="${Elo4_a} 0 ${Elo4_d}" rpy="${Elo4_alfa} 0 0" />
    </joint>

</robot>
